Workbook

Sheet Synthèse
A1: La Marinka — Synthèse du budget travaux (hors ameublement)
A3: Poste | B3: Total min € | C3: Total max € | D3: Auto min € | E3: Auto max € | F3: Montant retenu €
A4: Étage (4 chambres + 4 SdE + WC) | B4: ='Budget étage'!G39 | C4: ='Budget étage'!H39 | D4: ='Budget étage'!K39 | E4: ='Budget étage'!L39 | F4: ='Budget étage'!N39
A5: Rez-de-chaussée (séjour, baie galandage) | B5: ='Budget RDC'!G27 | C5: ='Budget RDC'!H27 | D5: ='Budget RDC'!K27 | E5: ='Budget RDC'!L27 | F5: ='Budget RDC'!N27
A6: Toiture 260 m² + ravalement des façades | B6: ='Budget Toiture'!G21 | C6: ='Budget Toiture'!H21 | D6: ='Budget Toiture'!K21 | E6: ='Budget Toiture'!L21 | F6: ='Budget Toiture'!N21
A7: TOTAL TRAVAUX TTC — sans sarking | B7: =SUM(B4:B6) | C7: =SUM(C4:C6) | D7: =SUM(D4:D6) | E7: =SUM(E4:E6) | F7: =SUM(F4:F6)
A8: Option sarking : surcoût net (onglet Toiture) | B8: ='Budget Toiture'!G33 | C8: ='Budget Toiture'!H33 | D8: ='Budget Toiture'!K33 | E8: ='Budget Toiture'!L33 | F8: ='Budget Toiture'!N33
A9: TOTAL TRAVAUX TTC — avec sarking | B9: =B7+B8 | C9: =C7+C8 | D9: =D7+D8 | E9: =E7+E8 | F9: =F7+F8
A11: Postes hors budget (Paramètres) | B11: =Paramètres!B14 | C11: =Paramètres!C14
A12: Enveloppe globale sans sarking | B12: =B7+B11 | C12: =C7+C11
A13: Enveloppe globale avec sarking | B13: =B9+B11 | C13: =C9+C11
A15: Ameublement non compris. Escalier compté une seule fois (onglet étage). Prix TTC indicatifs, à remplacer par les devis.

Sheet Budget étage
A1: La Marinka — Budget estimatif aménagement de l'étage (77 m²)
A2: Prix TTC indicatifs (marché France 2025-2026, entreprise), travaux seuls sans ameublement. Cellules en BLEU = à ajuster ; colonne JAUNE « Devis reçu » = à remplir au fil des devis.
A4: Lot | B4: Poste | C4: Unité | D4: Qté | E4: PU min € | F4: PU max € | G4: Total min € | H4: Total max € | I4: Faisable soi-même | J4: Part matériaux | K4: Auto min € | L4: Auto max € | M4: Devis reçu € | N4: Montant retenu € | O4: Commentaire
A5: Gros œuvre
B6: Nouvelle trémie, reprise solivage, rebouchage ancienne trémie | C6: forfait | D6: 1 | E6: 3000 | F6: 8000 | G6: =D6*E6 | H6: =D6*F6 | I6: Non | J6: 0.5 | K6: =IF(I6="Oui",G6*J6,G6) | L6: =IF(I6="Oui",H6*J6,H6) | N6: =IF(N(M6)>0,M6,(G6+H6)/2) | O6: Avis BET structure.
B7: Étude BET structure | C7: forfait | D7: 1 | E7: 1000 | F7: 2000 | G7: =D7*E7 | H7: =D7*F7 | I7: Non | J7: 0.5 | K7: =IF(I7="Oui",G7*J7,G7) | L7: =IF(I7="Oui",H7*J7,H7) | N7: =IF(N(M7)>0,M7,(G7+H7)/2)
B8: Escalier bois ¼ tournant sur mesure, posé | C8: u | D8: 1 | E8: 4000 | F8: 9000 | G8: =D8*E8 | H8: =D8*F8 | I8: Non | J8: 0.5 | K8: =IF(I8="Oui",G8*J8,G8) | L8: =IF(I8="Oui",H8*J8,H8) | N8: =IF(N(M8)>0,M8,(G8+H8)/2) | O8: Kit à poser soi-même : 1 500 – 3 000 €.
A9: Enveloppe / isolation
B10: Isolation rampants fibre de bois | C10: m² | D10: 100 | E10: 120 | F10: 250 | G10: =D10*E10 | H10: =D10*F10 | I10: Oui | J10: 0.55 | K10: =IF(I10="Oui",G10*J10,G10) | L10: =IF(I10="Oui",H10*J10,H10) | N10: =IF(N(M10)>0,M10,(G10+H10)/2) | O10: Surface de rampants à métrer.
B11: Velux 78×98 posés + raccords | C11: u | D11: 4 | E11: 1000 | F11: 1600 | G11: =D11*E11 | H11: =D11*F11 | I11: Non | J11: 0.6 | K11: =IF(I11="Oui",G11*J11,G11) | L11: =IF(I11="Oui",H11*J11,H11) | N11: =IF(N(M11)>0,M11,(G11+H11)/2) | O11: Étanchéité : à confier à un pro.
B12: Velux 55×78 posé (dégagement) | C12: u | D12: 1 | E12: 800 | F12: 1300 | G12: =D12*E12 | H12: =D12*F12 | I12: Non | J12: 0.6 | K12: =IF(I12="Oui",G12*J12,G12) | L12: =IF(I12="Oui",H12*J12,H12) | N12: =IF(N(M12)>0,M12,(G12+H12)/2)
B13: Doublage murs pisé (lame d'air + isolant perspirant + placo) | C13: m² | D13: 70 | E13: 75 | F13: 130 | G13: =D13*E13 | H13: =D13*F13 | I13: Oui | J13: 0.5 | K13: =IF(I13="Oui",G13*J13,G13) | L13: =IF(I13="Oui",H13*J13,H13) | N13: =IF(N(M13)>0,M13,(G13+H13)/2) | O13: Pas de pare-vapeur étanche.
A14: Cloisons / plafonds
B15: Cloisons placo 72/48 + laine (dont 2 en 10 cm galandage) | C15: m² | D15: 75 | E15: 55 | F15: 90 | G15: =D15*E15 | H15: =D15*F15 | I15: Oui | J15: 0.45 | K15: =IF(I15="Oui",G15*J15,G15) | L15: =IF(I15="Oui",H15*J15,H15) | N15: =IF(N(M15)>0,M15,(G15+H15)/2)
B16: Finition plafonds / habillage sous rampant | C16: m² | D16: 100 | E16: 40 | F16: 70 | G16: =D16*E16 | H16: =D16*F16 | I16: Oui | J16: 0.45 | K16: =IF(I16="Oui",G16*J16,G16) | L16: =IF(I16="Oui",H16*J16,H16) | N16: =IF(N(M16)>0,M16,(G16+H16)/2)
A17: Plomberie
B18: Salle d'eau complète (douche 120×80, vasque, sèche-serviettes) | C18: u | D18: 4 | E18: 5000 | F18: 9000 | G18: =D18*E18 | H18: =D18*F18 | I18: Non | J18: 0.5 | K18: =IF(I18="Oui",G18*J18,G18) | L18: =IF(I18="Oui",H18*J18,H18) | N18: =IF(N(M18)>0,M18,(G18+H18)/2) | O18: Poste le plus lourd.
B19: WC suspendu + lave-mains | C19: u | D19: 1 | E19: 1500 | F19: 3000 | G19: =D19*E19 | H19: =D19*F19 | I19: Non | J19: 0.5 | K19: =IF(I19="Oui",G19*J19,G19) | L19: =IF(I19="Oui",H19*J19,H19) | N19: =IF(N(M19)>0,M19,(G19+H19)/2)
B20: Réseaux alimentation / évacuations / chutes | C20: forfait | D20: 1 | E20: 500 | F20: 1000 | G20: =D20*E20 | H20: =D20*F20 | I20: Non | J20: 0.5 | K20: =IF(I20="Oui",G20*J20,G20) | L20: =IF(I20="Oui",H20*J20,H20) | N20: =IF(N(M20)>0,M20,(G20+H20)/2) | O20: 2 descentes (Est et Ouest).
B21: Production eau chaude (ballon 200-300 L) | C21: u | D21: 1 | E21: 2000 | F21: 4000 | G21: =D21*E21 | H21: =D21*F21 | I21: Non | J21: 0.6 | K21: =IF(I21="Oui",G21*J21,G21) | L21: =IF(I21="Oui",H21*J21,H21) | N21: =IF(N(M21)>0,M21,(G21+H21)/2) | O21: Thermodynamique = haut de fourchette.
A22: Électricité / ventilation / chauffage
B23: Électricité neuve NF C 15-100 | C23: m² | D23: 77 | E23: 80 | F23: 130 | G23: =D23*E23 | H23: =D23*F23 | I23: Non | J23: 0.4 | K23: =IF(I23="Oui",G23*J23,G23) | L23: =IF(I23="Oui",H23*J23,H23) | N23: =IF(N(M23)>0,M23,(G23+H23)/2)
B24: VMC hygro B (4 SdE + WC) | C24: u | D24: 1 | E24: 1500 | F24: 3000 | G24: =D24*E24 | H24: =D24*F24 | I24: Non | J24: 0.5 | K24: =IF(I24="Oui",G24*J24,G24) | L24: =IF(I24="Oui",H24*J24,H24) | N24: =IF(N(M24)>0,M24,(G24+H24)/2) | O24: Obligatoire : SdE et WC sans ouvrant.
B25: Chauffage (radiateurs inertie ou PAC air/air) | C25: forfait | D25: 1 | E25: 4000 | F25: 12000 | G25: =D25*E25 | H25: =D25*F25 | I25: Non | J25: 0.6 | K25: =IF(I25="Oui",G25*J25,G25) | L25: =IF(I25="Oui",H25*J25,H25) | N25: =IF(N(M25)>0,M25,(G25+H25)/2)
A26: Menuiseries intérieures
B27: Portes battantes posées | C27: u | D27: 7 | E27: 300 | F27: 550 | G27: =D27*E27 | H27: =D27*F27 | I27: Oui | J27: 0.6 | K27: =IF(I27="Oui",G27*J27,G27) | L27: =IF(I27="Oui",H27*J27,H27) | N27: =IF(N(M27)>0,M27,(G27+H27)/2) | O27: 4 chambres, SdE 3-4, WC.
B28: Portes à galandage (SdE 1-2) avec caisson | C28: u | D28: 2 | E28: 700 | F28: 1200 | G28: =D28*E28 | H28: =D28*F28 | I28: Oui | J28: 0.6 | K28: =IF(I28="Oui",G28*J28,G28) | L28: =IF(I28="Oui",H28*J28,H28) | N28: =IF(N(M28)>0,M28,(G28+H28)/2)
B29: Façades rangements sous rampant | C29: u | D29: 2 | E29: 300 | F29: 700 | G29: =D29*E29 | H29: =D29*F29 | I29: Oui | J29: 0.6 | K29: =IF(I29="Oui",G29*J29,G29) | L29: =IF(I29="Oui",H29*J29,H29) | N29: =IF(N(M29)>0,M29,(G29+H29)/2)
A30: Revêtements / finitions
B31: Parquet chambres + dégagement | C31: m² | D31: 51 | E31: 45 | F31: 90 | G31: =D31*E31 | H31: =D31*F31 | I31: Oui | J31: 0.6 | K31: =IF(I31="Oui",G31*J31,G31) | L31: =IF(I31="Oui",H31*J31,H31) | N31: =IF(N(M31)>0,M31,(G31+H31)/2)
B32: Carrelage sols SdE + WC | C32: m² | D32: 14 | E32: 70 | F32: 130 | G32: =D32*E32 | H32: =D32*F32 | I32: Oui | J32: 0.5 | K32: =IF(I32="Oui",G32*J32,G32) | L32: =IF(I32="Oui",H32*J32,H32) | N32: =IF(N(M32)>0,M32,(G32+H32)/2)
B33: Faïence murale SdE | C33: m² | D33: 40 | E33: 70 | F33: 130 | G33: =D33*E33 | H33: =D33*F33 | I33: Oui | J33: 0.5 | K33: =IF(I33="Oui",G33*J33,G33) | L33: =IF(I33="Oui",H33*J33,H33) | N33: =IF(N(M33)>0,M33,(G33+H33)/2)
B34: Peinture murs + plafonds | C34: m² | D34: 300 | E34: 20 | F34: 33 | G34: =D34*E34 | H34: =D34*F34 | I34: Oui | J34: 0.25 | K34: =IF(I34="Oui",G34*J34,G34) | L34: =IF(I34="Oui",H34*J34,H34) | N34: =IF(N(M34)>0,M34,(G34+H34)/2)
B36: Sous-total travaux | G36: =SUM(G5:G34) | H36: =SUM(H5:H34) | K36: =SUM(K5:K34) | L36: =SUM(L5:L34) | N36: =SUM(N5:N34)
B37: Imprévus | G37: =G36*Paramètres!$B$4 | H37: =H36*Paramètres!$B$4 | K37: =K36*Paramètres!$B$4 | L37: =L36*Paramètres!$B$4 | N37: =N36*Paramètres!$B$4
B38: Maîtrise d'œuvre | G38: =G36*Paramètres!$B$5 | H38: =H36*Paramètres!$B$5 | K38: =K36*Paramètres!$B$5 | L38: =L36*Paramètres!$B$5 | N38: =N36*Paramètres!$B$5
B39: TOTAL ÉTAGE TTC | G39: =G36+G37+G38 | H39: =H36+H37+H38 | K39: =K36+K37+K38 | L39: =L36+L37+L38 | N39: =N36+N37+N38
B40: Soit par m² (77 m²) | G40: =G39/77 | H40: =H39/77 | K40: =K39/77 | L40: =L39/77 | N40: =N39/77
B42: Lecture : « Total min / max » = fourchette entreprise. « Auto min / max » = coût si vous réalisez vous-même les postes marqués « Oui »
B43: (vous ne payez alors que la part matériaux). « Montant retenu » = devis reçu s'il est saisi, sinon la moyenne min/max.
...

Sheet Budget RDC
A1: La Marinka — Budget estimatif travaux du rez-de-chaussée (77 m²)
A2: Prix TTC indicatifs (marché France 2025-2026, entreprise), travaux seuls sans ameublement. Cellules en BLEU = à ajuster ; colonne JAUNE « Devis reçu » = à remplir au fil des devis.
A4: Lot | B4: Poste | C4: Unité | D4: Qté | E4: PU min € | F4: PU max € | G4: Total min € | H4: Total max € | I4: Faisable soi-même | J4: Part matériaux | K4: Auto min € | L4: Auto max € | M4: Devis reçu € | N4: Montant retenu € | O4: Commentaire
A5: Gros œuvre / structure
B6: Ouverture 4 m dans le pisé : étaiement, linteau béton ou acier, reprises | C6: forfait | D6: 1 | E6: 6000 | F6: 15000 | G6: =D6*E6 | H6: =D6*F6 | I6: Non | J6: 0.4 | K6: =IF(I6="Oui",G6*J6,G6) | L6: =IF(I6="Oui",H6*J6,H6) | N6: =IF(N(M6)>0,M6,(G6+H6)/2) | O6: Intervention la plus lourde du RDC.
B7: Étude BET structure (baie 4 m) | C7: forfait | D7: 1 | E7: 1000 | F7: 2500 | G7: =D7*E7 | H7: =D7*F7 | I7: Non | J7: 0.5 | K7: =IF(I7="Oui",G7*J7,G7) | L7: =IF(I7="Oui",H7*J7,H7) | N7: =IF(N(M7)>0,M7,(G7+H7)/2) | O7: Obligatoire dans le pisé.
B8: Sol : décaissement, hérisson ventilé, dalle isolée (chaux ou béton) | C8: m² | D8: 72 | E8: 90 | F8: 180 | G8: =D8*E8 | H8: =D8*F8 | I8: Non | J8: 0.45 | K8: =IF(I8="Oui",G8*J8,G8) | L8: =IF(I8="Oui",H8*J8,H8) | N8: =IF(N(M8)>0,M8,(G8+H8)/2) | O8: Sol de grange brut ; dalle respirante conseillée avec le pisé.
A9: Menuiseries extérieures
B10: Baie vitrée 4,00 m à galandage, 2 vantaux, posée | C10: u | D10: 1 | E10: 12000 | F10: 25000 | G10: =D10*E10 | H10: =D10*F10 | I10: Non | J10: 0.7 | K10: =IF(I10="Oui",G10*J10,G10) | L10: =IF(I10="Oui",H10*J10,H10) | N10: =IF(N(M10)>0,M10,(G10+H10)/2) | O10: Alu ou bois-alu, double vitrage ; caissons compris.
B11: Seuil, bavette, raccords d'étanchéité baie | C11: forfait | D11: 1 | E11: 800 | F11: 2000 | G11: =D11*E11 | H11: =D11*F11 | I11: Non | J11: 0.5 | K11: =IF(I11="Oui",G11*J11,G11) | L11: =IF(I11="Oui",H11*J11,H11) | N11: =IF(N(M11)>0,M11,(G11+H11)/2)
A12: Isolation / doublage / plafond
B13: Doublage murs pisé (lame d'air + isolant perspirant + placo) | C13: m² | D13: 79 | E13: 75 | F13: 130 | G13: =D13*E13 | H13: =D13*F13 | I13: Oui | J13: 0.5 | K13: =IF(I13="Oui",G13*J13,G13) | L13: =IF(I13="Oui",H13*J13,H13) | N13: =IF(N(M13)>0,M13,(G13+H13)/2) | O13: Périmètre 34 m × 2,60 m − baie.
B14: Doublage épaissi au droit des caissons galandage | C14: ml | D14: 4 | E14: 150 | F14: 300 | G14: =D14*E14 | H14: =D14*F14 | I14: Oui | J14: 0.5 | K14: =IF(I14="Oui",G14*J14,G14) | L14: =IF(I14="Oui",H14*J14,H14) | N14: =IF(N(M14)>0,M14,(G14+H14)/2) | O14: 2 × 2 m.
B15: Plafond sous plancher étage + isolation phonique | C15: m² | D15: 72 | E15: 45 | F15: 80 | G15: =D15*E15 | H15: =D15*F15 | I15: Oui | J15: 0.45 | K15: =IF(I15="Oui",G15*J15,G15) | L15: =IF(I15="Oui",H15*J15,H15) | N15: =IF(N(M15)>0,M15,(G15+H15)/2) | O15: Ou poutres apparentes traitées.
A16: Électricité / chauffage
B17: Électricité séjour (prises, réseau, mur TV, éclairages table et billard) | C17: m² | D17: 72 | E17: 70 | F17: 110 | G17: =D17*E17 | H17: =D17*F17 | I17: Non | J17: 0.4 | K17: =IF(I17="Oui",G17*J17,G17) | L17: =IF(I17="Oui",H17*J17,H17) | N17: =IF(N(M17)>0,M17,(G17+H17)/2)
B18: Chauffage (poêle à bois ou PAC air/air) | C18: forfait | D18: 1 | E18: 4000 | F18: 12000 | G18: =D18*E18 | H18: =D18*F18 | I18: Non | J18: 0.6 | K18: =IF(I18="Oui",G18*J18,G18) | L18: =IF(I18="Oui",H18*J18,H18) | N18: =IF(N(M18)>0,M18,(G18+H18)/2) | O18: Poêle : conduit compris.
A19: Revêtements / finitions
B20: Revêtement de sol (parquet massif ou terre cuite) | C20: m² | D20: 72 | E20: 50 | F20: 110 | G20: =D20*E20 | H20: =D20*F20 | I20: Oui | J20: 0.6 | K20: =IF(I20="Oui",G20*J20,G20) | L20: =IF(I20="Oui",H20*J20,H20) | N20: =IF(N(M20)>0,M20,(G20+H20)/2)
B21: Peinture / enduits murs + plafond | C21: m² | D21: 150 | E21: 20 | F21: 35 | G21: =D21*E21 | H21: =D21*F21 | I21: Oui | J21: 0.25 | K21: =IF(I21="Oui",G21*J21,G21) | L21: =IF(I21="Oui",H21*J21,H21) | N21: =IF(N(M21)>0,M21,(G21+H21)/2) | O21: Enduit chaux possible.
B22: Plinthes, finitions, habillage escalier | C22: forfait | D22: 1 | E22: 600 | F22: 1500 | G22: =D22*E22 | H22: =D22*F22 | I22: Oui | J22: 0.5 | K22: =IF(I22="Oui",G22*J22,G22) | L22: =IF(I22="Oui",H22*J22,H22) | N22: =IF(N(M22)>0,M22,(G22+H22)/2) | O22: Escalier : compté dans l'onglet étage.
B24: Sous-total travaux | G24: =SUM(G5:G22) | H24: =SUM(H5:H22) | K24: =SUM(K5:K22) | L24: =SUM(L5:L22) | N24: =SUM(N5:N22)
B25: Imprévus | G25: =G24*Paramètres!$B$4 | H25: =H24*Paramètres!$B$4 | K25: =K24*Paramètres!$B$4 | L25: =L24*Paramètres!$B$4 | N25: =N24*Paramètres!$B$4
B26: Maîtrise d'œuvre | G26: =G24*Paramètres!$B$5 | H26: =H24*Paramètres!$B$5 | K26: =K24*Paramètres!$B$5 | L26: =L24*Paramètres!$B$5 | N26: =N24*Paramètres!$B$5
B27: TOTAL RDC TTC | G27: =G24+G25+G26 | H27: =H24+H25+H26 | K27: =K24+K25+K26 | L27: =L24+L25+L26 | N27: =N24+N25+N26
B28: Soit par m² (77 m²) | G28: =G27/77 | H28: =H27/77 | K28: =K27/77 | L28: =L27/77 | N28: =N27/77
B30: Lecture : « Total min / max » = fourchette entreprise. « Auto min / max » = coût si vous réalisez vous-même les postes marqués « Oui »
B31: (vous ne payez alors que la part matériaux). « Montant retenu » = devis reçu s'il est saisi, sinon la moyenne min/max.
B32: Source : estimations indicatives de prix moyens du marché (ordre de grandeur), à remplacer par les devis d'artisans.

Sheet Budget Toiture
A1: La Marinka — Budget estimatif toiture (260 m²) et ravalement des façades
A2: Prix TTC indicatifs (marché France 2025-2026, entreprise), travaux seuls sans ameublement. Cellules en BLEU = à ajuster ; colonne JAUNE « Devis reçu » = à remplir au fil des devis.
A4: Lot | B4: Poste | C4: Unité | D4: Qté | E4: PU min € | F4: PU max € | G4: Total min € | H4: Total max € | I4: Faisable soi-même | J4: Part matériaux | K4: Auto min € | L4: Auto max € | M4: Devis reçu € | N4: Montant retenu € | O4: Commentaire
A5: Couverture (260 m²)
B6: Dépose de la couverture existante + évacuation | C6: m² | D6: 260 | E6: 15 | F6: 30 | G6: =D6*E6 | H6: =D6*F6 | I6: Non | J6: 0.3 | K6: =IF(I6="Oui",G6*J6,G6) | L6: =IF(I6="Oui",H6*J6,H6) | N6: =IF(N(M6)>0,M6,(G6+H6)/2)
B7: Écran sous-toiture HPV + contre-liteaux + liteaux neufs | C7: m² | D7: 260 | E7: 25 | F7: 45 | G7: =D7*E7 | H7: =D7*F7 | I7: Non | J7: 0.5 | K7: =IF(I7="Oui",G7*J7,G7) | L7: =IF(I7="Oui",H7*J7,H7) | N7: =IF(N(M7)>0,M7,(G7+H7)/2)
B8: Tuiles neuves terre cuite, fourniture + pose | C8: m² | D8: 260 | E8: 50 | F8: 90 | G8: =D8*E8 | H8: =D8*F8 | I8: Non | J8: 0.6 | K8: =IF(I8="Oui",G8*J8,G8) | L8: =IF(I8="Oui",H8*J8,H8) | N8: =IF(N(M8)>0,M8,(G8+H8)/2) | O8: Tuiles canal / anciennes : prendre le haut de fourchette ou plus.
B9: Faîtage, rives, arêtiers (scellés ou à sec) | C9: ml | D9: 60 | E9: 35 | F9: 70 | G9: =D9*E9 | H9: =D9*F9 | I9: Non | J9: 0.5 | K9: =IF(I9="Oui",G9*J9,G9) | L9: =IF(I9="Oui",H9*J9,H9) | N9: =IF(N(M9)>0,M9,(G9+H9)/2) | O9: Linéaire à métrer.
B10: Zinguerie : gouttières, descentes, noues | C10: ml | D10: 40 | E10: 40 | F10: 80 | G10: =D10*E10 | H10: =D10*F10 | I10: Non | J10: 0.5 | K10: =IF(I10="Oui",G10*J10,G10) | L10: =IF(I10="Oui",H10*J10,H10) | N10: =IF(N(M10)>0,M10,(G10+H10)/2) | O10: Zinc ou alu.
A11: Façades (maison + grange)
B12: Ravalement sur pisé : piquage, réparations, enduit chaux 3 couches | C12: m² | D12: 400 | E12: 60 | F12: 120 | G12: =D12*E12 | H12: =D12*F12 | I12: Non | J12: 0.35 | K12: =IF(I12="Oui",G12*J12,G12) | L12: =IF(I12="Oui",H12*J12,H12) | N12: =IF(N(M12)>0,M12,(G12+H12)/2) | O12: Surface de façades à métrer (≈ 250 m² grange + 150 à 250 m² maison). Jamais d'enduit ciment sur le pisé.
B13: Encadrements, appuis, soubassement drainant (anti-remontées) | C13: forfait | D13: 1 | E13: 2000 | F13: 6000 | G13: =D13*E13 | H13: =D13*F13 | I13: Non | J13: 0.4 | K13: =IF(I13="Oui",G13*J13,G13) | L13: =IF(I13="Oui",H13*J13,H13) | N13: =IF(N(M13)>0,M13,(G13+H13)/2)
A14: Charpente / sécurité
B15: Reprise ponctuelle de charpente + traitement insectes / champignons | C15: forfait | D15: 1 | E15: 2000 | F15: 10000 | G15: =D15*E15 | H15: =D15*F15 | I15: Non | J15: 0.4 | K15: =IF(I15="Oui",G15*J15,G15) | L15: =IF(I15="Oui",H15*J15,H15) | N15: =IF(N(M15)>0,M15,(G15+H15)/2) | O15: Selon diagnostic ; reprise lourde non comprise.
B16: Échafaudage, protections, sécurité (toiture + façades) | C16: forfait | D16: 1 | E16: 4000 | F16: 10000 | G16: =D16*E16 | H16: =D16*F16 | I16: Non | J16: 0.3 | K16: =IF(I16="Oui",G16*J16,G16) | L16: =IF(I16="Oui",H16*J16,H16) | N16: =IF(N(M16)>0,M16,(G16+H16)/2) | O16: À mutualiser entre couvreur et façadier.
B18: Sous-total travaux | G18: =SUM(G5:G16) | H18: =SUM(H5:H16) | K18: =SUM(K5:K16) | L18: =SUM(L5:L16) | N18: =SUM(N5:N16)
B19: Imprévus | G19: =G18*Paramètres!$B$4 | H19: =H18*Paramètres!$B$4 | K19: =K18*Paramètres!$B$4 | L19: =L18*Paramètres!$B$4 | N19: =N18*Paramètres!$B$4
B20: Maîtrise d'œuvre | G20: =G18*Paramètres!$B$5 | H20: =H18*Paramètres!$B$5 | K20: =K18*Paramètres!$B$5 | L20: =L18*Paramètres!$B$5 | N20: =N18*Paramètres!$B$5
B21: TOTAL TOITURE + FAÇADES TTC (sans sarking) | G21: =G18+G19+G20 | H21: =H18+H19+H20 | K21: =K18+K19+K20 | L21: =L18+L19+L20 | N21: =N18+N19+N20
B22: Soit par m² (260 m²) | G22: =G21/260 | H22: =H21/260 | K22: =K21/260 | L22: =L21/260 | N22: =N21/260
B24: Lecture : « Total min / max » = fourchette entreprise. « Auto min / max » = coût si vous réalisez vous-même les postes marqués « Oui »
B25: (vous ne payez alors que la part matériaux). « Montant retenu » = devis reçu s'il est saisi, sinon la moyenne min/max.
B26: Source : estimations indicatives de prix moyens du marché (ordre de grandeur), à remplacer par les devis d'artisans.
A28: OPTION SARKING | B28: Isolation posée par l'extérieur pendant la réfection (remplace l'isolation intérieure des rampants de l'étage)
B29: Isolation sarking fibre de bois 160-200 mm + pare-pluie (sur chevrons) | C29: m² | D29: 260 | E29: 80 | F29: 150 | G29: =D29*E29 | H29: =D29*F29 | I29: Non | J29: 0.55 | K29: =IF(I29="Oui",G29*J29,G29) | L29: =IF(I29="Oui",H29*J29,H29) | N29: =IF(N(M29)>0,M29,(G29+H29)/2) | O29: Charpente apparente à l'étage, R ≈ 4 à 5.
B30: Rehausse des rives et adaptation zinguerie à l'épaisseur d'isolant | C30: forfait | D30: 1 | E30: 1500 | F30: 4000 | G30: =D30*E30 | H30: =D30*F30 | I30: Non | J30: 0.5 | K30: =IF(I30="Oui",G30*J30,G30) | L30: =IF(I30="Oui",H30*J30,H30) | N30: =IF(N(M30)>0,M30,(G30+H30)/2)
B31: Sous-total option sarking | G31: =SUM(G29:G30) | H31: =SUM(H29:H30) | K31: =SUM(K29:K30) | L31: =SUM(L29:L30) | N31: =SUM(N29:N30)
B32: Économie : isolation intérieure des rampants supprimée (onglet étage) | G32: =-'Budget étage'!G10 | H32: =-'Budget étage'!H10 | K32: =-'Budget étage'!K10 | L32: =-'Budget étage'!L10 | N32: =-'Budget étage'!N10
B33: SURCOÛT NET OPTION SARKING TTC (imprévus + MOE inclus) | G33: =(G31+G32)*(1+Paramètres!$B$4+Paramètres!$B$5) | H33: =(H31+H32)*(1+Paramètres!$B$4+Paramètres!$B$5) | K33: =(K31+K32)*(1+Paramètres!$B$4+Paramètres!$B$5) | L33: =(L31+L32)*(1+Paramètres!$B$4+Paramètres!$B$5) | N33: =(N31+N32)*(1+Paramètres!$B$4+Paramètres!$B$5)
B35: Le sarking garde la charpente apparente, libère quelques cm de hauteur sous rampant et facilite la pose étanche des Velux.

Sheet Paramètres
A1: La Marinka — Paramètres et postes hors budget
A3: Paramètre | B3: Valeur | C3: Commentaire
A4: Imprévus (% des travaux) | B4: 0.1 | C4: Usuel en rénovation de bâti ancien : 10 à 15 %.
A5: Maîtrise d'œuvre / architecte (% des travaux) | B5: 0 | C5: 0 % si vous pilotez vous-même ; 8 à 12 % avec un maître d'œuvre.
A7: TVA : prix affichés TTC à 20 % (création de surface habitable dans une grange : taux réduit en principe non applicable).
A9: Postes HORS budget étage (à chiffrer séparément)
A10: Poste | B10: Min € | C10: Max € | D10: Commentaire
A11: Raccordements eau / électricité / assainissement individuel | B11: 8000 | C11: 15000 | D11: Selon raccordement existant de la grange.
A12: Renfort du plancher / chape | B12: 5000 | C12: 12000 | D12: Si le plancher de l'étage est insuffisant.
A13: Taxe d'aménagement + dossier changement de destination | B13: 2000 | C13: 5000 | D13: Selon taux communal et départemental.
A14: Total hors budget | B14: =SUM(B11:B13) | C14: =SUM(C11:C13)
